<?xml version="1.0" ?>
<!-- =================================================================================== -->
<!-- |    This document was autogenerated by xacro from /daniel/Desktop/evo_pipe/catkin_ws/src/experiment_settings/urdf/ur5e_4f.urdf.xacro | -->
<!-- |    EDITING THIS FILE BY HAND IS NOT RECOMMENDED                                 | -->
<!-- =================================================================================== -->
<!-- =================================================================================== -->
<!-- |    This document was autogenerated by xacro from ./src/experiment_settings/urdf/ur5e_sim.xacro | -->
<!-- |    EDITING THIS FILE BY HAND IS NOT RECOMMENDED                                 | -->
<!-- =================================================================================== -->
<robot name="ur5e_robot">
    <gazebo>
        <plugin filename="libgazebo_ros_control.so" name="gazebo_ros_control">
            <!--robotNamespace>/</robotNamespace-->
            <robotSimType>gazebo_ros_control/DefaultRobotHWSim</robotSimType>
            <legacyModeNS>true</legacyModeNS>
            <robotNamespace>/</robotNamespace>
        </plugin>
        <!--
    <plugin name="gazebo_ros_power_monitor_controller" filename="libgazebo_ros_power_monitor.so">
      <alwaysOn>true</alwaysOn>
      <updateRate>1.0</updateRate>
      <timeout>5</timeout>
      <powerStateTopic>power_state</powerStateTopic>
      <powerStateRate>10.0</powerStateRate>
      <fullChargeCapacity>87.78</fullChargeCapacity>     
      <dischargeRate>-474</dischargeRate>
      <chargeRate>525</chargeRate>
      <dischargeVoltage>15.52</dischargeVoltage>
      <chargeVoltage>16.41</chargeVoltage>
    </plugin>
-->
    </gazebo>
    <!--property name="shoulder_height" value="0.089159" /-->
    <!--property name="shoulder_offset" value="0.13585" /-->
    <!-- shoulder_offset - elbow_offset + wrist_1_length = 0.10915 -->
    <!--property name="upper_arm_length" value="0.42500" /-->
    <!--property name="elbow_offset" value="0.1197" /-->
    <!-- CAD measured -->
    <!--property name="forearm_length" value="0.39225" /-->
    <!--property name="wrist_1_length" value="0.093" /-->
    <!-- CAD measured -->
    <!--property name="wrist_2_length" value="0.09465" /-->
    <!-- In CAD this distance is 0.930, but in the spec it is 0.09465 -->
    <!--property name="wrist_3_length" value="0.0823" /-->
    <!-- manually measured -->
    <link name="base_link">
        <visual>
            <geometry>
                <mesh filename="package://experiment_settings/meshes/visual/base.dae" />
            </geometry>
            <material name="LightGrey">
                <color rgba="0.7 0.7 0.7 1.0" />
            </material>
        </visual>
        <collision>
            <geometry>
                <mesh filename="package://experiment_settings/meshes/collision/base.stl" />
            </geometry>
        </collision>
        <inertial>
            <mass value="4.0" />
            <origin rpy="0 0 0" xyz="0.0 0.0 0.0" />
            <inertia ixx="0.00443333156" ixy="0.0" ixz="0.0" iyy="0.00443333156" iyz="0.0" izz="0.0072" />
        </inertial>
    </link>
    <joint name="shoulder_pan_joint" type="revolute">
        <parent link="base_link" />
        <child link="shoulder_link" />
        <origin rpy="0.0 0.0 0.0" xyz="0.0 0.0 0.163" />
        <axis xyz="0 0 1" />
        <limit effort="150.0" lower="-3.141592653589793" upper="3.141592653589793" velocity="3.14" />
        <dynamics damping="0.0" friction="0.0" />
    </joint>
    <link name="shoulder_link">
        <visual>
            <geometry>
                <mesh filename="package://experiment_settings/meshes/visual/shoulder.dae" />
            </geometry>
            <material name="LightGrey">
                <color rgba="0.7 0.7 0.7 1.0" />
            </material>
        </visual>
        <collision>
            <geometry>
                <mesh filename="package://experiment_settings/meshes/collision/shoulder.stl" />
            </geometry>
        </collision>
        <inertial>
            <mass value="3.7" />
            <origin rpy="0 0 0" xyz="0.0 0.0 0.0" />
            <inertia ixx="0.010267495893" ixy="0.0" ixz="0.0" iyy="0.010267495893" iyz="0.0" izz="0.00666" />
        </inertial>
    </link>
    <joint name="shoulder_lift_joint" type="revolute">
        <parent link="shoulder_link" />
        <child link="upper_arm_link" />
        <origin rpy="0.0 1.5707963267948966 0.0" xyz="0.0 0.138 0.0" />
        <axis xyz="0 1 0" />
        <limit effort="150.0" lower="-3.141592653589793" upper="3.141592653589793" velocity="3.14" />
        <dynamics damping="0.0" friction="0.0" />
    </joint>
    <link name="upper_arm_link">
        <visual>
            <geometry>
                <mesh filename="package://experiment_settings/meshes/visual/upperarm.dae" />
            </geometry>
            <material name="LightGrey">
                <color rgba="0.7 0.7 0.7 1.0" />
            </material>
        </visual>
        <collision>
            <geometry>
                <mesh filename="package://experiment_settings/meshes/collision/upperarm.stl" />
            </geometry>
        </collision>
        <inertial>
            <mass value="8.393" />
            <origin rpy="0 0 0" xyz="0.0 0.0 0.2125" />
            <inertia ixx="0.1338857818623325" ixy="0.0" ixz="0.0" iyy="0.1338857818623325" iyz="0.0" izz="0.0151074" />
        </inertial>
    </link>
    <joint name="elbow_joint" type="revolute">
        <parent link="upper_arm_link" />
        <child link="forearm_link" />
        <origin rpy="0.0 0.0 0.0" xyz="0.0 -0.131 0.425" />
        <axis xyz="0 1 0" />
        <limit effort="150.0" lower="-3.141592653589793" upper="3.141592653589793" velocity="3.14" />
        <dynamics damping="0.0" friction="0.0" />
    </joint>
    <link name="forearm_link">
        <visual>
            <geometry>
                <mesh filename="package://experiment_settings/meshes/visual/forearm.dae" />
            </geometry>
            <material name="LightGrey">
                <color rgba="0.7 0.7 0.7 1.0" />
            </material>
        </visual>
        <collision>
            <geometry>
                <mesh filename="package://experiment_settings/meshes/collision/forearm.stl" />
            </geometry>
        </collision>
        <inertial>
            <mass value="2.275" />
            <origin rpy="0 0 0" xyz="0.0 0.0 0.196" />
            <inertia ixx="0.031179620861480004" ixy="0.0" ixz="0.0" iyy="0.031179620861480004" iyz="0.0" izz="0.004095" />
        </inertial>
    </link>
    <joint name="wrist_1_joint" type="revolute">
        <parent link="forearm_link" />
        <child link="wrist_1_link" />
        <origin rpy="0.0 1.5707963267948966 0.0" xyz="0.0 0.0 0.392" />
        <axis xyz="0 1 0" />
        <limit effort="28.0" lower="-3.141592653589793" upper="3.141592653589793" velocity="6.28" />
        <dynamics damping="0.0" friction="0.0" />
    </joint>
    <link name="wrist_1_link">
        <visual>
            <geometry>
                <mesh filename="package://experiment_settings/meshes/visual/wrist1.dae" />
            </geometry>
            <material name="LightGrey">
                <color rgba="0.7 0.7 0.7 1.0" />
            </material>
        </visual>
        <collision>
            <geometry>
                <mesh filename="package://experiment_settings/meshes/collision/wrist1.stl" />
            </geometry>
        </collision>
        <inertial>
            <mass value="1.219" />
            <origin rpy="0 0 0" xyz="0.0 0.127 0.0" />
            <inertia ixx="0.0025598989760400002" ixy="0.0" ixz="0.0" iyy="0.0025598989760400002" iyz="0.0" izz="0.0021942" />
        </inertial>
    </link>
    <joint name="wrist_2_joint" type="revolute">
        <parent link="wrist_1_link" />
        <child link="wrist_2_link" />
        <origin rpy="0.0 0.0 0.0" xyz="0.0 0.127 0.0" />
        <axis xyz="0 0 1" />
        <limit effort="28.0" lower="-3.141592653589793" upper="3.141592653589793" velocity="6.28" />
        <dynamics damping="0.0" friction="0.0" />
    </joint>
    <link name="wrist_2_link">
        <visual>
            <geometry>
                <mesh filename="package://experiment_settings/meshes/visual/wrist2.dae" />
            </geometry>
            <material name="LightGrey">
                <color rgba="0.7 0.7 0.7 1.0" />
            </material>
        </visual>
        <collision>
            <geometry>
                <mesh filename="package://experiment_settings/meshes/collision/wrist2.stl" />
            </geometry>
        </collision>
        <inertial>
            <mass value="1.219" />
            <origin rpy="0 0 0" xyz="0.0 0.0 0.1" />
            <inertia ixx="0.0025598989760400002" ixy="0.0" ixz="0.0" iyy="0.0025598989760400002" iyz="0.0" izz="0.0021942" />
        </inertial>
    </link>
    <joint name="wrist_3_joint" type="revolute">
        <parent link="wrist_2_link" />
        <child link="wrist_3_link" />
        <origin rpy="0.0 0.0 0.0" xyz="0.0 0.0 0.1" />
        <axis xyz="0 1 0" />
        <limit effort="28.0" lower="-3.141592653589793" upper="3.141592653589793" velocity="6.28" />
        <dynamics damping="0.0" friction="0.0" />
    </joint>
    <link name="wrist_3_link">
        <visual>
            <geometry>
                <mesh filename="package://experiment_settings/meshes/visual/wrist3.dae" />
            </geometry>
            <material name="LightGrey">
                <color rgba="0.7 0.7 0.7 1.0" />
            </material>
        </visual>
        <collision>
            <geometry>
                <mesh filename="package://experiment_settings/meshes/collision/wrist3.stl" />
            </geometry>
        </collision>
        <inertial>
            <mass value="0.1879" />
            <origin rpy="1.5707963267948966 0 0" xyz="0.0 0.0771 0.0" />
            <inertia ixx="9.890410052167731e-05" ixy="0.0" ixz="0.0" iyy="9.890410052167731e-05" iyz="0.0" izz="0.0001321171875" />
        </inertial>
    </link>
    <joint name="ee_fixed_joint" type="fixed">
        <parent link="wrist_3_link" />
        <child link="ee_link" />
        <origin rpy="0.0 0.0 1.5707963267948966" xyz="0.0 0.1 0.0" />
    </joint>
    <link name="ee_link">
        <collision>
            <geometry>
                <box size="0.01 0.01 0.01" />
            </geometry>
            <origin rpy="0 0 0" xyz="-0.01 0 0" />
        </collision>
        <inertial>
            <mass value="0.1" />
            <origin rpy="0 0 0" xyz="0 0 0" />
            <inertia ixx="0.03" ixy="0.0" ixz="0.0" iyy="0.03" iyz="0.0" izz="0.03" />
        </inertial>
    </link>
    <transmission name="shoulder_pan_trans">
        <type>transmission_interface/SimpleTransmission</type>
        <joint name="shoulder_pan_joint">
            <hardwareInterface>hardware_interface/PositionJointInterface</hardwareInterface>
        </joint>
        <actuator name="shoulder_pan_motor">
            <mechanicalReduction>1</mechanicalReduction>
            <hardwareInterface>hardware_interface/PositionJointInterface</hardwareInterface>
        </actuator>
    </transmission>
    <transmission name="shoulder_lift_trans">
        <type>transmission_interface/SimpleTransmission</type>
        <joint name="shoulder_lift_joint">
            <hardwareInterface>hardware_interface/PositionJointInterface</hardwareInterface>
        </joint>
        <actuator name="shoulder_lift_motor">
            <mechanicalReduction>1</mechanicalReduction>
            <hardwareInterface>hardware_interface/PositionJointInterface</hardwareInterface>
        </actuator>
    </transmission>
    <transmission name="elbow_trans">
        <type>transmission_interface/SimpleTransmission</type>
        <joint name="elbow_joint">
            <hardwareInterface>hardware_interface/PositionJointInterface</hardwareInterface>
        </joint>
        <actuator name="elbow_motor">
            <mechanicalReduction>1</mechanicalReduction>
            <hardwareInterface>hardware_interface/PositionJointInterface</hardwareInterface>
        </actuator>
    </transmission>
    <transmission name="wrist_1_trans">
        <type>transmission_interface/SimpleTransmission</type>
        <joint name="wrist_1_joint">
            <hardwareInterface>hardware_interface/PositionJointInterface</hardwareInterface>
        </joint>
        <actuator name="wrist_1_motor">
            <mechanicalReduction>1</mechanicalReduction>
            <hardwareInterface>hardware_interface/PositionJointInterface</hardwareInterface>
        </actuator>
    </transmission>
    <transmission name="wrist_2_trans">
        <type>transmission_interface/SimpleTransmission</type>
        <joint name="wrist_2_joint">
            <hardwareInterface>hardware_interface/PositionJointInterface</hardwareInterface>
        </joint>
        <actuator name="wrist_2_motor">
            <mechanicalReduction>1</mechanicalReduction>
            <hardwareInterface>hardware_interface/PositionJointInterface</hardwareInterface>
        </actuator>
    </transmission>
    <transmission name="wrist_3_trans">
        <type>transmission_interface/SimpleTransmission</type>
        <joint name="wrist_3_joint">
            <hardwareInterface>hardware_interface/PositionJointInterface</hardwareInterface>
        </joint>
        <actuator name="wrist_3_motor">
            <mechanicalReduction>1</mechanicalReduction>
            <hardwareInterface>hardware_interface/PositionJointInterface</hardwareInterface>
        </actuator>
    </transmission>
    <gazebo reference="shoulder_link">
        <selfCollide>true</selfCollide>
    </gazebo>
    <gazebo reference="upper_arm_link">
        <selfCollide>true</selfCollide>
    </gazebo>
    <gazebo reference="forearm_link">
        <selfCollide>true</selfCollide>
    </gazebo>
    <gazebo reference="wrist_1_link">
        <selfCollide>true</selfCollide>
    </gazebo>
    <gazebo reference="wrist_3_link">
        <selfCollide>true</selfCollide>
    </gazebo>
    <gazebo reference="wrist_2_link">
        <selfCollide>true</selfCollide>
    </gazebo>
    <gazebo reference="ee_link">
        <selfCollide>true</selfCollide>
    </gazebo>
    <!-- ROS base_link to UR 'Base' Coordinates transform -->
    <link name="base" />
    <joint name="base_link-base_fixed_joint" type="fixed">
        <!-- NOTE: this rotation is only needed as long as base_link itself is
                 not corrected wrt the real robot (ie: rotated over 180
                 degrees)
      -->
        <origin rpy="0 0 -3.141592653589793" xyz="0 0 0" />
        <parent link="base_link" />
        <child link="base" />
    </joint>
    <!-- Frame coincident with all-zeros TCP on UR controller -->
    <link name="tool0" />
    <joint name="wrist_3_link-tool0_fixed_joint" type="fixed">
        <origin rpy="-1.5707963267948966 0 0" xyz="0 0.1 0" />
        <parent link="wrist_3_link" />
        <child link="tool0" />
    </joint>
    <material name="camera_aluminum">
        <color rgba="0.5 0.5 0.5 1" />
    </material>
    <!-- camera body, with origin at bottom screw mount -->
    <joint name="camera_joint" type="fixed">
        <origin rpy="3.1414 0.0 1.5707" xyz="0.05472 0.014 0.03" />
        <parent link="ur_gripper" />
        <child link="camera_bottom_screw_frame" />
    </joint>
    <link name="camera_bottom_screw_frame" />
    <joint name="camera_link_joint" type="fixed">
        <origin rpy="0 0 0" xyz="0 0.0175 0.0125" />
        <parent link="camera_bottom_screw_frame" />
        <child link="camera_link" />
    </joint>
    <link name="camera_link">
        <visual>
            <origin rpy="1.5707963267948966 0 1.5707963267948966" xyz="0.0149 -0.0175 0" />
            <geometry>
                <!-- <box size="${d435_cam_width} ${d435_cam_height} ${d435_cam_depth}"/> -->
                <mesh filename="package://experiment_settings/meshes/d435_sim.dae" />
                <!--<mesh filename="package://realsense2_description/meshes/d435/d435.dae" />-->
            </geometry>
            <material name="camera_aluminum" />
        </visual>
        <collision>
            <origin rpy="0 0 0" xyz="0 -0.0175 0" />
            <geometry>
                <box size="0.02505 0.09 0.025" />
            </geometry>
        </collision>
        <inertial>
            <!-- The following are not reliable values, and should not be used for modeling -->
            <mass value="0.564" />
            <origin xyz="0 0 0" rpy="0 0 0" />
            <inertia ixx="0.003881243" ixy="0.0" ixz="0.0" iyy="0.000498940" iyz="0.0" izz="0.003879257" />
        </inertial>
    </link>
    <!-- camera depth joints and links -->
    <joint name="camera_depth_joint" type="fixed">
        <origin rpy="0 0 0" xyz="0 0 0" />
        <parent link="camera_link" />
        <child link="camera_depth_frame" />
    </joint>
    <link name="camera_depth_frame" />
    <joint name="camera_depth_optical_joint" type="fixed">
        <origin rpy="-1.5707963267948966 0 -1.5707963267948966" xyz="0 0 0" />
        <parent link="camera_depth_frame" />
        <child link="camera_depth_optical_frame" />
    </joint>
    <link name="camera_depth_optical_frame" />
    <!-- camera left IR joints and links -->
    <joint name="camera_left_ir_joint" type="fixed">
        <origin rpy="0 0 0" xyz="0 0.0 0" />
        <parent link="camera_depth_frame" />
        <child link="camera_left_ir_frame" />
    </joint>
    <link name="camera_left_ir_frame" />
    <joint name="camera_left_ir_optical_joint" type="fixed">
        <origin rpy="-1.5707963267948966 0 -1.5707963267948966" xyz="0 0 0" />
        <parent link="camera_left_ir_frame" />
        <child link="camera_left_ir_optical_frame" />
    </joint>
    <link name="camera_left_ir_optical_frame" />
    <!-- camera right IR joints and links -->
    <joint name="camera_right_ir_joint" type="fixed">
        <origin rpy="0 0 0" xyz="0 -0.05 0" />
        <parent link="camera_depth_frame" />
        <child link="camera_right_ir_frame" />
    </joint>
    <link name="camera_right_ir_frame" />
    <joint name="camera_right_ir_optical_joint" type="fixed">
        <origin rpy="-1.5707963267948966 0 -1.5707963267948966" xyz="0 0 0" />
        <parent link="camera_right_ir_frame" />
        <child link="camera_right_ir_optical_frame" />
    </joint>
    <link name="camera_right_ir_optical_frame" />
    <!-- camera color joints and links -->
    <joint name="camera_color_joint" type="fixed">
        <origin rpy="0 0 0" xyz="0 0.015 0" />
        <parent link="camera_depth_frame" />
        <child link="camera_color_frame" />
    </joint>
    <link name="camera_color_frame" />
    <joint name="camera_color_optical_joint" type="fixed">
        <origin rpy="-1.5707963267948966 0 -1.5707963267948966" xyz="0 0 0" />
        <parent link="camera_color_frame" />
        <child link="camera_color_optical_frame" />
    </joint>
    <link name="camera_color_optical_frame" />
    <gazebo reference="camera_link">
        <self_collide>0</self_collide>
        <enable_wind>0</enable_wind>
        <kinematic>0</kinematic>
        <gravity>1</gravity>
        <!--<mu>1</mu>-->
        <mu2>1</mu2>
        <fdir1>0 0 0</fdir1>
        <!--<slip1>0</slip1>
      <slip2>0</slip2>-->
        <kp>1e+13</kp>
        <kd>1</kd>
        <!--<max_vel>0.01</max_vel>
      <min_depth>0</min_depth>-->
        <sensor name="cameracolor" type="camera">
            <camera name="camera">
                <horizontal_fov>1.2112585008840648</horizontal_fov>
                <image>
                    <width>640</width>
                    <height>480</height>
                    <format>RGB_INT8</format>
                </image>
                <clip>
                    <near>0.1</near>
                    <far>100</far>
                </clip>
                <noise>
                    <type>gaussian</type>
                    <mean>0.0</mean>
                    <stddev>0.007</stddev>
                </noise>
            </camera>
            <always_on>1</always_on>
            <update_rate>30</update_rate>
            <visualize>1</visualize>
        </sensor>
        <sensor name="cameraired1" type="camera">
            <camera name="camera">
                <horizontal_fov>1.4870205226991688</horizontal_fov>
                <image>
                    <width>640</width>
                    <height>480</height>
                    <format>L_INT8</format>
                </image>
                <clip>
                    <near>0.1</near>
                    <far>100</far>
                </clip>
                <noise>
                    <type>gaussian</type>
                    <mean>0.0</mean>
                    <stddev>0.05</stddev>
                </noise>
            </camera>
            <always_on>1</always_on>
            <update_rate>90</update_rate>
            <visualize>0</visualize>
        </sensor>
        <sensor name="cameraired2" type="camera">
            <camera name="camera">
                <horizontal_fov>1.4870205226991688</horizontal_fov>
                <image>
                    <width>640</width>
                    <height>480</height>
                    <format>L_INT8</format>
                </image>
                <clip>
                    <near>0.1</near>
                    <far>100</far>
                </clip>
                <noise>
                    <type>gaussian</type>
                    <mean>0.0</mean>
                    <stddev>0.05</stddev>
                </noise>
            </camera>
            <always_on>1</always_on>
            <update_rate>90</update_rate>
            <visualize>0</visualize>
        </sensor>
        <sensor name="cameradepth" type="depth">
            <camera name="camera">
                <horizontal_fov>1.4870205226991688</horizontal_fov>
                <image>
                    <width>640</width>
                    <height>480</height>
                </image>
                <clip>
                    <near>0.1</near>
                    <far>100</far>
                </clip>
                <noise>
                    <type>gaussian</type>
                    <mean>0.0</mean>
                    <stddev>0.100</stddev>
                </noise>
            </camera>
            <always_on>1</always_on>
            <update_rate>90</update_rate>
            <visualize>0</visualize>
        </sensor>
    </gazebo>
    <gazebo>
        <plugin filename="librealsense_gazebo_plugin.so" name="camera">
            <prefix>camera</prefix>
            <depthUpdateRate>30.0</depthUpdateRate>
            <colorUpdateRate>30.0</colorUpdateRate>
            <infraredUpdateRate>30.0</infraredUpdateRate>
            <depthTopicName>depth/image_raw</depthTopicName>
            <depthCameraInfoTopicName>depth/camera_info</depthCameraInfoTopicName>
            <colorTopicName>color/image_raw</colorTopicName>
            <colorCameraInfoTopicName>color/camera_info</colorCameraInfoTopicName>
            <infrared1TopicName>infra1/image_raw</infrared1TopicName>
            <infrared1CameraInfoTopicName>infra1/camera_info</infrared1CameraInfoTopicName>
            <infrared2TopicName>infra2/image_raw</infrared2TopicName>
            <infrared2CameraInfoTopicName>infra2/camera_info</infrared2CameraInfoTopicName>
            <colorOpticalframeName>camera_color_optical_frame</colorOpticalframeName>
            <depthOpticalframeName>camera_depth_optical_frame</depthOpticalframeName>
            <infrared1OpticalframeName>camera_left_ir_optical_frame</infrared1OpticalframeName>
            <infrared2OpticalframeName>camera_right_ir_optical_frame</infrared2OpticalframeName>
            <rangeMinDepth>0.2</rangeMinDepth>
            <rangeMaxDepth>10.0</rangeMaxDepth>
            <pointCloud>True</pointCloud>
            <pointCloudTopicName>depth/color/points</pointCloudTopicName>
            <pointCloudCutoff>0.25</pointCloudCutoff>
            <pointCloudCutoffMax>9.0</pointCloudCutoffMax>
        </plugin>
    </gazebo>
    <link name="ur_gripper">
        <visual>
            <geometry>
                <mesh filename="package://experiment_settings/stl/ur_gripper.stl" scale="0.001 0.001 0.001" />
            </geometry>
        </visual>
        <collision>
            <geometry>
                <mesh filename="package://experiment_settings/stl/ur_gripper.stl" scale="0.001 0.001 0.001" />
            </geometry>
        </collision>
        <inertial>
            <mass value="0.1" />
            <origin rpy="0 0 0" xyz="0 0 0" />
            <inertia ixx="0.03" ixy="0.0" ixz="0.0" iyy="0.03" iyz="0.0" izz="0.03" />
        </inertial>
    </link>
    <joint name="ur_gripper_joint" type="fixed">
        <parent link="ee_link" />
        <child link="ur_gripper" />
        <origin rpy="0.0 -0.7854 -1.57" xyz="-0.002 -0.08423 -0.15968" />
    </joint>
    <!-- ============================================================================= -->
    <!-- PALM -->
    <link name="palm_link">
        <visual>
            <geometry>
                <mesh filename="package://allegro_hand_description/meshes/base_link_left.STL" />
            </geometry>
            <origin rpy="-1.5707963259 0 0" xyz="0 0 0 " />
            <material name="black">
                <color rgba="0.2 0.2 0.2 1" />
            </material>
        </visual>
        <collision>
            <origin rpy="0 0 0" xyz="-0.009300 0 -0.0475" />
            <geometry>
                <box size="0.0408 0.1130 0.095" />
            </geometry>
        </collision>
        <inertial>
            <origin rpy="0 0 0" xyz="0 0 0.0475" />
            <mass value="0.4154" />
            <inertia ixx="0" ixy="0.0" ixz="0.0" iyy="0" iyz="0.0" izz="0" />
        </inertial>
    </link>
    <!-- ============================================================================= -->
    <!-- END THUMB MACRO -->
    <!-- [[END]] THREE FINGER MACRO -->
    <!-- [LINK 0, 4, 8] -->
    <link name="link_8">
        <visual>
            <geometry>
                <mesh filename="package://allegro_hand_description/meshes/link_0.0.STL" />
            </geometry>
            <material name="black" />
        </visual>
        <collision>
            <geometry>
                <box size="0.0196 0.0275 0.0164" />
            </geometry>
            <origin rpy="0 0 0" xyz="0 0 0.0082" />
        </collision>
        <inertial>
            <mass value="0.0119" />
            <origin rpy="0 0 0" xyz="0 0 0" />
            <inertia ixx="0" ixy="0.0" ixz="0.0" iyy="0" iyz="0.0" izz="0" />
        </inertial>
    </link>
    <joint name="joint_8" type="revolute">
        <axis xyz="0 0 1" />
        <limit effort="15" lower="-0.47" upper="0.47" velocity="7" />
        <parent link="palm_link" />
        <child link="link_8" />
        <origin rpy="-0.08726646254999999 0 0" xyz="0 0.0435 -0.001542" />
        <dynamics damping="3" friction="10" />
    </joint>
    <!-- [LINK 1, 5, 9] -->
    <link name="link_9">
        <visual>
            <geometry>
                <mesh filename="package://allegro_hand_description/meshes/link_1.0.STL" />
            </geometry>
            <material name="black" />
        </visual>
        <collision>
            <geometry>
                <box size="0.0196 0.0275 0.054" />
            </geometry>
            <origin rpy="0 0 0" xyz="0 0 0.027" />
        </collision>
        <inertial>
            <mass value="0.065" />
            <origin rpy="0 0 0" xyz="0 0 0" />
            <inertia ixx="0" ixy="0" ixz="0" iyy="0" iyz="0" izz="0" />
        </inertial>
    </link>
    <joint name="joint_9" type="revolute">
        <limit effort="15" lower="-0.19599999999999998" upper="1.6099999999999999" velocity="7" />
        <axis xyz="0 1 0" />
        <parent link="link_8" />
        <child link="link_9" />
        <origin xyz="0 0 0.0164" />
        <dynamics damping="3" friction="5" />
    </joint>
    <!-- [LINK 2, 6, 10]-->
    <link name="link_10">
        <visual>
            <geometry>
                <mesh filename="package://allegro_hand_description/meshes/link_2.0.STL" />
            </geometry>
            <material name="black" />
        </visual>
        <collision>
            <geometry>
                <box size="0.0196 0.0275 0.0384" />
            </geometry>
            <origin rpy="0 0 0" xyz="0 0 0.0192" />
        </collision>
        <inertial>
            <mass value="0.0355" />
            <origin rpy="0 0 0" xyz="0 0 0" />
            <inertia ixx="0" ixy="0" ixz="0" iyy="0" iyz="0" izz="0" />
        </inertial>
    </link>
    <joint name="joint_10" type="revolute">
        <axis xyz="0 1 0" />
        <limit effort="15" lower="-0.17400000000000002" upper="1.7089999999999999" velocity="7" />
        <parent link="link_9" />
        <child link="link_10" />
        <origin xyz="0 0 0.054" />
        <dynamics damping="8" friction="10" />
    </joint>
    <!-- [LINK 3, 7, 11] -->
    <link name="link_11">
        <visual>
            <geometry>
                <mesh filename="package://allegro_hand_description/meshes/link_3.0.STL" />
            </geometry>
            <material name="black" />
        </visual>
        <collision>
            <geometry>
                <box size="0.0196 0.0275 0.026699999999999998" />
            </geometry>
            <origin rpy="0 0 0" xyz="0 0 0.013349999999999999" />
        </collision>
        <inertial>
            <mass value="0.0096" />
            <origin rpy="0 0 0" xyz="0 0 0" />
            <inertia ixx="0" ixy="0" ixz="0" iyy="0" iyz="0" izz="0" />
        </inertial>
    </link>
    <joint name="joint_11" type="revolute">
        <axis xyz="0 1 0" />
        <limit effort="15" lower="-0.227" upper="1.6179999999999999" velocity="7" />
        <parent link="link_10" />
        <child link="link_11" />
        <origin xyz="0 0 0.0384" />
        <dynamics damping="10" friction="12" />
    </joint>
    <!-- [FINGER TIP] -->
    <link name="link_11_tip">
        <visual>
            <geometry>
                <mesh filename="package://allegro_hand_description/meshes/link_3.0_tip.STL" />
            </geometry>
            <material name="white">
                <color rgba=".9 .9 .9 1" />
            </material>
        </visual>
        <collision>
            <geometry>
                <sphere radius="0.012" />
            </geometry>
        </collision>
        <inertial>
            <mass value="0.0168" />
            <origin rpy="0 0 0" xyz="0 0 0" />
            <inertia ixx="0" ixy="0" ixz="0" iyy="0" iyz="0" izz="0" />
        </inertial>
    </link>
    <joint name="joint_11_tip" type="fixed">
        <parent link="link_11" />
        <child link="link_11_tip" />
        <origin rpy="0 0 0" xyz="0 0 0.026699999999999998" />
    </joint>
    <!-- [LINK 0, 4, 8] -->
    <link name="link_4">
        <visual>
            <geometry>
                <mesh filename="package://allegro_hand_description/meshes/link_0.0.STL" />
            </geometry>
            <material name="black" />
        </visual>
        <collision>
            <geometry>
                <box size="0.0196 0.0275 0.0164" />
            </geometry>
            <origin rpy="0 0 0" xyz="0 0 0.0082" />
        </collision>
        <inertial>
            <mass value="0.0119" />
            <origin rpy="0 0 0" xyz="0 0 0" />
            <inertia ixx="0" ixy="0.0" ixz="0.0" iyy="0" iyz="0.0" izz="0" />
        </inertial>
    </link>
    <joint name="joint_4" type="revolute">
        <axis xyz="0 0 1" />
        <limit effort="15" lower="-0.47" upper="0.47" velocity="7" />
        <parent link="palm_link" />
        <child link="link_4" />
        <origin rpy="0.0 0 0" xyz="0 0 0.0007" />
        <dynamics damping="3" friction="10" />
    </joint>
    <!-- [LINK 1, 5, 9] -->
    <link name="link_5">
        <visual>
            <geometry>
                <mesh filename="package://allegro_hand_description/meshes/link_1.0.STL" />
            </geometry>
            <material name="black" />
        </visual>
        <collision>
            <geometry>
                <box size="0.0196 0.0275 0.054" />
            </geometry>
            <origin rpy="0 0 0" xyz="0 0 0.027" />
        </collision>
        <inertial>
            <mass value="0.065" />
            <origin rpy="0 0 0" xyz="0 0 0" />
            <inertia ixx="0" ixy="0" ixz="0" iyy="0" iyz="0" izz="0" />
        </inertial>
    </link>
    <joint name="joint_5" type="revolute">
        <limit effort="15" lower="-0.19599999999999998" upper="1.6099999999999999" velocity="7" />
        <axis xyz="0 1 0" />
        <parent link="link_4" />
        <child link="link_5" />
        <origin xyz="0 0 0.0164" />
        <dynamics damping="3" friction="5" />
    </joint>
    <!-- [LINK 2, 6, 10]-->
    <link name="link_6">
        <visual>
            <geometry>
                <mesh filename="package://allegro_hand_description/meshes/link_2.0.STL" />
            </geometry>
            <material name="black" />
        </visual>
        <collision>
            <geometry>
                <box size="0.0196 0.0275 0.0384" />
            </geometry>
            <origin rpy="0 0 0" xyz="0 0 0.0192" />
        </collision>
        <inertial>
            <mass value="0.0355" />
            <origin rpy="0 0 0" xyz="0 0 0" />
            <inertia ixx="0" ixy="0" ixz="0" iyy="0" iyz="0" izz="0" />
        </inertial>
    </link>
    <joint name="joint_6" type="revolute">
        <axis xyz="0 1 0" />
        <limit effort="15" lower="-0.17400000000000002" upper="1.7089999999999999" velocity="7" />
        <parent link="link_5" />
        <child link="link_6" />
        <origin xyz="0 0 0.054" />
        <dynamics damping="8" friction="10" />
    </joint>
    <!-- [LINK 3, 7, 11] -->
    <link name="link_7">
        <visual>
            <geometry>
                <mesh filename="package://allegro_hand_description/meshes/link_3.0.STL" />
            </geometry>
            <material name="black" />
        </visual>
        <collision>
            <geometry>
                <box size="0.0196 0.0275 0.026699999999999998" />
            </geometry>
            <origin rpy="0 0 0" xyz="0 0 0.013349999999999999" />
        </collision>
        <inertial>
            <mass value="0.0096" />
            <origin rpy="0 0 0" xyz="0 0 0" />
            <inertia ixx="0" ixy="0" ixz="0" iyy="0" iyz="0" izz="0" />
        </inertial>
    </link>
    <joint name="joint_7" type="revolute">
        <axis xyz="0 1 0" />
        <limit effort="15" lower="-0.227" upper="1.6179999999999999" velocity="7" />
        <parent link="link_6" />
        <child link="link_7" />
        <origin xyz="0 0 0.0384" />
        <dynamics damping="10" friction="12" />
    </joint>
    <!-- [FINGER TIP] -->
    <link name="link_7_tip">
        <visual>
            <geometry>
                <mesh filename="package://allegro_hand_description/meshes/link_3.0_tip.STL" />
            </geometry>
            <material name="white">
                <color rgba=".9 .9 .9 1" />
            </material>
        </visual>
        <collision>
            <geometry>
                <sphere radius="0.012" />
            </geometry>
        </collision>
        <inertial>
            <mass value="0.0168" />
            <origin rpy="0 0 0" xyz="0 0 0" />
            <inertia ixx="0" ixy="0" ixz="0" iyy="0" iyz="0" izz="0" />
        </inertial>
    </link>
    <joint name="joint_7_tip" type="fixed">
        <parent link="link_7" />
        <child link="link_7_tip" />
        <origin rpy="0 0 0" xyz="0 0 0.026699999999999998" />
    </joint>
    <!-- [LINK 0, 4, 8] -->
    <link name="link_0">
        <visual>
            <geometry>
                <mesh filename="package://allegro_hand_description/meshes/link_0.0.STL" />
            </geometry>
            <material name="black" />
        </visual>
        <collision>
            <geometry>
                <box size="0.0196 0.0275 0.0164" />
            </geometry>
            <origin rpy="0 0 0" xyz="0 0 0.0082" />
        </collision>
        <inertial>
            <mass value="0.0119" />
            <origin rpy="0 0 0" xyz="0 0 0" />
            <inertia ixx="0" ixy="0.0" ixz="0.0" iyy="0" iyz="0.0" izz="0" />
        </inertial>
    </link>
    <joint name="joint_0" type="revolute">
        <axis xyz="0 0 1" />
        <limit effort="15" lower="-0.47" upper="0.47" velocity="7" />
        <parent link="palm_link" />
        <child link="link_0" />
        <origin rpy="0.08726646254999999 0 0" xyz="0 -0.0435 -0.001542" />
        <dynamics damping="3" friction="10" />
    </joint>
    <!-- [LINK 1, 5, 9] -->
    <link name="link_1">
        <visual>
            <geometry>
                <mesh filename="package://allegro_hand_description/meshes/link_1.0.STL" />
            </geometry>
            <material name="black" />
        </visual>
        <collision>
            <geometry>
                <box size="0.0196 0.0275 0.054" />
            </geometry>
            <origin rpy="0 0 0" xyz="0 0 0.027" />
        </collision>
        <inertial>
            <mass value="0.065" />
            <origin rpy="0 0 0" xyz="0 0 0" />
            <inertia ixx="0" ixy="0" ixz="0" iyy="0" iyz="0" izz="0" />
        </inertial>
    </link>
    <joint name="joint_1" type="revolute">
        <limit effort="15" lower="-0.19599999999999998" upper="1.6099999999999999" velocity="7" />
        <axis xyz="0 1 0" />
        <parent link="link_0" />
        <child link="link_1" />
        <origin xyz="0 0 0.0164" />
        <dynamics damping="3" friction="5" />
    </joint>
    <!-- [LINK 2, 6, 10]-->
    <link name="link_2">
        <visual>
            <geometry>
                <mesh filename="package://allegro_hand_description/meshes/link_2.0.STL" />
            </geometry>
            <material name="black" />
        </visual>
        <collision>
            <geometry>
                <box size="0.0196 0.0275 0.0384" />
            </geometry>
            <origin rpy="0 0 0" xyz="0 0 0.0192" />
        </collision>
        <inertial>
            <mass value="0.0355" />
            <origin rpy="0 0 0" xyz="0 0 0" />
            <inertia ixx="0" ixy="0" ixz="0" iyy="0" iyz="0" izz="0" />
        </inertial>
    </link>
    <joint name="joint_2" type="revolute">
        <axis xyz="0 1 0" />
        <limit effort="15" lower="-0.17400000000000002" upper="1.7089999999999999" velocity="7" />
        <parent link="link_1" />
        <child link="link_2" />
        <origin xyz="0 0 0.054" />
        <dynamics damping="8" friction="10" />
    </joint>
    <!-- [LINK 3, 7, 11] -->
    <link name="link_3">
        <visual>
            <geometry>
                <mesh filename="package://allegro_hand_description/meshes/link_3.0.STL" />
            </geometry>
            <material name="black" />
        </visual>
        <collision>
            <geometry>
                <box size="0.0196 0.0275 0.026699999999999998" />
            </geometry>
            <origin rpy="0 0 0" xyz="0 0 0.013349999999999999" />
        </collision>
        <inertial>
            <mass value="0.0096" />
            <origin rpy="0 0 0" xyz="0 0 0" />
            <inertia ixx="0" ixy="0" ixz="0" iyy="0" iyz="0" izz="0" />
        </inertial>
    </link>
    <joint name="joint_3" type="revolute">
        <axis xyz="0 1 0" />
        <limit effort="15" lower="-0.227" upper="1.6179999999999999" velocity="7" />
        <parent link="link_2" />
        <child link="link_3" />
        <origin xyz="0 0 0.0384" />
        <dynamics damping="10" friction="12" />
    </joint>
    <!-- [FINGER TIP] -->
    <link name="link_3_tip">
        <visual>
            <geometry>
                <mesh filename="package://allegro_hand_description/meshes/link_3.0_tip.STL" />
            </geometry>
            <material name="white">
                <color rgba=".9 .9 .9 1" />
            </material>
        </visual>
        <collision>
            <geometry>
                <sphere radius="0.012" />
            </geometry>
        </collision>
        <inertial>
            <mass value="0.0168" />
            <origin rpy="0 0 0" xyz="0 0 0" />
            <inertia ixx="0" ixy="0" ixz="0" iyy="0" iyz="0" izz="0" />
        </inertial>
    </link>
    <joint name="joint_3_tip" type="fixed">
        <parent link="link_3" />
        <child link="link_3_tip" />
        <origin rpy="0 0 0" xyz="0 0 0.026699999999999998" />
    </joint>
    <!-- [LINK 12] -->
    <link name="link_12">
        <visual>
            <geometry>
                <mesh filename="package://allegro_hand_description/meshes/link_12.0_left.STL" />
            </geometry>
            <material name="black">
                <color rgba=".2 .2 .2 1" />
            </material>
            <origin rpy="3.1415926518 0 0" xyz="0 0 0" />
        </visual>
        <collision>
            <geometry>
                <box size="0.0358 0.034 0.0455" />
            </geometry>
            <origin rpy="0 0 0" xyz="-0.0179 -0.009 0.0145" />
        </collision>
        <inertial>
            <mass value="0.0176" />
            <origin rpy="0 0 0" xyz="0 0 0" />
            <inertia ixx="0" ixy="0" ixz="0" iyy="0" iyz="0" izz="0" />
        </inertial>
    </link>
    <joint name="joint_12" type="revolute">
        <axis xyz="+1 0 0" />
        <limit effort="15" lower="0.263" upper="1.396" velocity="7" />
        <parent link="palm_link" />
        <child link="link_12" />
        <origin rpy="0 -1.6580627884499999 1.5707963259" xyz="-0.0182 -0.019333 -0.045987" />
        <dynamics damping="3" friction="10" />
    </joint>
    <!-- [LINK 13] -->
    <link name="link_13">
        <visual>
            <geometry>
                <mesh filename="package://allegro_hand_description/meshes/link_13.0.STL" />
            </geometry>
            <material name="black">
                <color rgba=".2 .2 .2 1" />
            </material>
        </visual>
        <collision>
            <geometry>
                <box size="0.0196 0.0275 0.0177" />
            </geometry>
            <origin rpy="0 0 0" xyz="0 0 0.00885" />
        </collision>
        <inertial>
            <mass value="0.0119" />
            <origin rpy="0 0 0" xyz="0 0 0" />
            <inertia ixx="0" ixy="0" ixz="0" iyy="0" iyz="0" izz="0" />
        </inertial>
    </link>
    <joint name="joint_13" type="revolute">
        <axis xyz="0 0 -1" />
        <limit effort="15" lower="-0.10499999999999998" upper="1.1629999999999998" velocity="7" />
        <parent link="link_12" />
        <child link="link_13" />
        <origin xyz="-0.027 -0.005 0.0399" />
        <dynamics damping="3" friction="5" />
    </joint>
    <!-- [LINK 14] -->
    <link name="link_14">
        <visual>
            <geometry>
                <mesh filename="package://allegro_hand_description/meshes/link_14.0.STL" />
            </geometry>
            <material name="black" />
        </visual>
        <collision>
            <geometry>
                <box size="0.0196 0.0275 0.0514" />
            </geometry>
            <origin rpy="0 0 0" xyz="0 0 0.0257" />
        </collision>
        <inertial>
            <mass value="0.038" />
            <origin rpy="0 0 0" xyz="0 0 0" />
            <inertia ixx="0" ixy="0" ixz="0" iyy="0" iyz="0" izz="0" />
        </inertial>
    </link>
    <joint name="joint_14" type="revolute">
        <axis xyz="0 1 0" />
        <limit effort="15" lower="-0.18899999999999997" upper="1.644" velocity="7" />
        <parent link="link_13" />
        <child link="link_14" />
        <origin xyz="0 0 0.0177" />
        <dynamics damping="3" friction="10" />
    </joint>
    <!-- [LINK 15] -->
    <link name="link_15">
        <visual>
            <geometry>
                <mesh filename="package://allegro_hand_description/meshes/link_15.0.STL" />
            </geometry>
            <material name="black" />
        </visual>
        <collision>
            <geometry>
                <box size="0.0196 0.0275 0.042300000000000004" />
            </geometry>
            <origin rpy="0 0 0" xyz="0 0 0.021150000000000002" />
        </collision>
        <inertial>
            <mass value="0.0388" />
            <origin rpy="0 0 0" xyz="0 0 0" />
            <inertia ixx="0" ixy="0" ixz="0" iyy="0" iyz="0" izz="0" />
        </inertial>
    </link>
    <joint name="joint_15" type="revolute">
        <axis xyz="0 1 0" />
        <limit effort="15" lower="-0.162" upper="1.7189999999999999" velocity="7" />
        <parent link="link_14" />
        <child link="link_15" />
        <origin xyz="0 0 0.0514" />
        <dynamics damping="3" friction="12" />
    </joint>
    <!-- [FINGER TIP] -->
    <link name="link_15_tip">
        <visual>
            <geometry>
                <mesh filename="package://allegro_hand_description/meshes/link_15.0_tip.STL" />
            </geometry>
            <material name="white">
                <color rgba=".9 .9 .9 1" />
            </material>
        </visual>
        <collision>
            <geometry>
                <sphere radius="0.012" />
            </geometry>
            <origin rpy="0 0 0" xyz="0 0 0" />
        </collision>
        <inertial>
            <mass value="0.0168" />
            <origin rpy="0 0 0" xyz="0 0 0" />
            <inertia ixx="0" ixy="0" ixz="0" iyy="0" iyz="0" izz="0" />
        </inertial>
    </link>
    <joint name="joint_15_tip" type="fixed">
        <parent link="link_15" />
        <child link="link_15_tip" />
        <origin rpy="0 0 0" xyz="0 0 0.042300000000000004" />
    </joint>
    <joint name="palm_2_ur" type="fixed">
        <parent link="ee_link" />
        <child link="palm_link" />
        <origin rpy="-0.0 0 0" xyz="0.05 0 0.05" />    <!-- SI QUIERES DE LAO, rpy="-1.57 0 0" -->
    </joint>
    <material name="grey">
        <color rgba="0.6627 0.6627 0.6627 1.0" />
    </material>
    <material name="black">
        <color rgba="0.0 0.0 0.0 1.0" />
    </material>
    <!-- other elements -->
    <link name="base_cylinder">
        <origin rpy="0 0 0" xyz="0 0 0" />
        <visual>
            <geometry>
                <cylinder length="0.70" radius="0.2" />
            </geometry>
            <material name="grey" />
        </visual>
        <colision>
            <geometry>
                <cylinder length="0.70" radius="0.2" />
            </geometry>
        </colision>
    </link>
    <link name="ground">
        <origin rpy="0 0 0" xyz="0 0 0" />
        <visual>
            <geometry>
                <box size="0.01 3.0 3.0" />
            </geometry>
            <material name="black" />
        </visual>
        <colision>
            <geometry>
                <box size="0.01 3.0 3.0" />
            </geometry>
        </colision>
    </link>
    <link name="table">
        <visual>
            <geometry>
                <mesh filename="package://experiment_settings/stl/mesa_lab.stl" scale="0.001 0.001 0.001" />
            </geometry>
        </visual>
        <collision>
            <geometry>
                <mesh filename="package://experiment_settings/stl/mesa_lab.stl" scale="0.001 0.001 0.001" />
            </geometry>
        </collision>
        <inertial>
            <mass value="1000" />
            <inertia ixx="1.22289588e+13" ixy="1.94030569e+05" ixz="2.85818883e+06" iyy="1.38362428e+13" iyz="3.28817310e+05" izz="3.81996609e+12" />
            <origin xyz="0 0 0" rpy="0 0 0" />
        </inertial>
    </link>
    <!-- construction -->
    <link name="world" />
    <joint name="world_ground_joint" type="fixed">
        <parent link="world" />
        <child link="ground" />
        <origin rpy="0.0 1.57 0.0" xyz="0.0 0.0 0.0" />
    </joint>
    <joint name="world_base_joint" type="fixed">
        <parent link="world" />
        <child link="base_cylinder" />
        <origin rpy="0.0 0.0 0.0" xyz="0.0 0.0 0.35" />
    </joint>
    <joint name="base_robot_joint" type="fixed">
        <parent link="base_cylinder" />
        <child link="base_link" />
        <origin rpy="0.0 0.0 0.0" xyz="0.0 0.0 0.35" />
    </joint>
    <joint name="world_table_joint" type="fixed">
        <parent link="world" />
        <child link="table" />
        <origin rpy="-1.57 0.0 -1.57" xyz="-0.2 1.0 0.74" />
    </joint>
    <transmission name="trans_joint_8">
        <type>transmission_interface/SimpleTransmission</type>
        <joint name="joint_8">
            <hardwareInterface>hardware_interface/PositionJointInterface</hardwareInterface>
        </joint>
        <actuator name="joint_8_motor">
            <hardwareInterface>hardware_interface/PositionJointInterface</hardwareInterface>
            <mechanicalReduction>1</mechanicalReduction>
        </actuator>
    </transmission>
    <transmission name="trans_joint_9">
        <type>transmission_interface/SimpleTransmission</type>
        <joint name="joint_9">
            <hardwareInterface>hardware_interface/PositionJointInterface</hardwareInterface>
        </joint>
        <actuator name="joint_9_motor">
            <hardwareInterface>hardware_interface/PositionJointInterface</hardwareInterface>
            <mechanicalReduction>1</mechanicalReduction>
        </actuator>
    </transmission>
    <transmission name="trans_joint_10">
        <type>transmission_interface/SimpleTransmission</type>
        <joint name="joint_10">
            <hardwareInterface>hardware_interface/PositionJointInterface</hardwareInterface>
        </joint>
        <actuator name="joint_10_motor">
            <hardwareInterface>hardware_interface/PositionJointInterface</hardwareInterface>
            <mechanicalReduction>1</mechanicalReduction>
        </actuator>
    </transmission>
    <transmission name="trans_joint_11">
        <type>transmission_interface/SimpleTransmission</type>
        <joint name="joint_11">
            <hardwareInterface>hardware_interface/PositionJointInterface</hardwareInterface>
        </joint>
        <actuator name="joint_11_motor">
            <hardwareInterface>hardware_interface/PositionJointInterface</hardwareInterface>
            <mechanicalReduction>1</mechanicalReduction>
        </actuator>
    </transmission>
    <transmission name="trans_joint_4">
        <type>transmission_interface/SimpleTransmission</type>
        <joint name="joint_4">
            <hardwareInterface>hardware_interface/PositionJointInterface</hardwareInterface>
        </joint>
        <actuator name="joint_4_motor">
            <hardwareInterface>hardware_interface/PositionJointInterface</hardwareInterface>
            <mechanicalReduction>1</mechanicalReduction>
        </actuator>
    </transmission>
    <transmission name="trans_joint_5">
        <type>transmission_interface/SimpleTransmission</type>
        <joint name="joint_5">
            <hardwareInterface>hardware_interface/PositionJointInterface</hardwareInterface>
        </joint>
        <actuator name="joint_5_motor">
            <hardwareInterface>hardware_interface/PositionJointInterface</hardwareInterface>
            <mechanicalReduction>1</mechanicalReduction>
        </actuator>
    </transmission>
    <transmission name="trans_joint_6">
        <type>transmission_interface/SimpleTransmission</type>
        <joint name="joint_6">
            <hardwareInterface>hardware_interface/PositionJointInterface</hardwareInterface>
        </joint>
        <actuator name="joint_6_motor">
            <hardwareInterface>hardware_interface/PositionJointInterface</hardwareInterface>
            <mechanicalReduction>1</mechanicalReduction>
        </actuator>
    </transmission>
    <transmission name="trans_joint_7">
        <type>transmission_interface/SimpleTransmission</type>
        <joint name="joint_7">
            <hardwareInterface>hardware_interface/PositionJointInterface</hardwareInterface>
        </joint>
        <actuator name="joint_7_motor">
            <hardwareInterface>hardware_interface/PositionJointInterface</hardwareInterface>
            <mechanicalReduction>1</mechanicalReduction>
        </actuator>
    </transmission>
    <transmission name="trans_joint_0">
        <type>transmission_interface/SimpleTransmission</type>
        <joint name="joint_0">
            <hardwareInterface>hardware_interface/PositionJointInterface</hardwareInterface>
        </joint>
        <actuator name="joint_0_motor">
            <hardwareInterface>hardware_interface/PositionJointInterface</hardwareInterface>
            <mechanicalReduction>1</mechanicalReduction>
        </actuator>
    </transmission>
    <transmission name="trans_joint_1">
        <type>transmission_interface/SimpleTransmission</type>
        <joint name="joint_1">
            <hardwareInterface>hardware_interface/PositionJointInterface</hardwareInterface>
        </joint>
        <actuator name="joint_1_motor">
            <hardwareInterface>hardware_interface/PositionJointInterface</hardwareInterface>
            <mechanicalReduction>1</mechanicalReduction>
        </actuator>
    </transmission>
    <transmission name="trans_joint_2">
        <type>transmission_interface/SimpleTransmission</type>
        <joint name="joint_2">
            <hardwareInterface>hardware_interface/PositionJointInterface</hardwareInterface>
        </joint>
        <actuator name="joint_2_motor">
            <hardwareInterface>hardware_interface/PositionJointInterface</hardwareInterface>
            <mechanicalReduction>1</mechanicalReduction>
        </actuator>
    </transmission>
    <transmission name="trans_joint_3">
        <type>transmission_interface/SimpleTransmission</type>
        <joint name="joint_3">
            <hardwareInterface>hardware_interface/PositionJointInterface</hardwareInterface>
        </joint>
        <actuator name="joint_3_motor">
            <hardwareInterface>hardware_interface/PositionJointInterface</hardwareInterface>
            <mechanicalReduction>1</mechanicalReduction>
        </actuator>
    </transmission>
    <transmission name="trans_joint_12">
        <type>transmission_interface/SimpleTransmission</type>
        <joint name="joint_12">
            <hardwareInterface>hardware_interface/PositionJointInterface</hardwareInterface>
        </joint>
        <actuator name="joint_12_motor">
            <hardwareInterface>hardware_interface/PositionJointInterface</hardwareInterface>
            <mechanicalReduction>1</mechanicalReduction>
        </actuator>
    </transmission>
    <transmission name="trans_joint_13">
        <type>transmission_interface/SimpleTransmission</type>
        <joint name="joint_13">
            <hardwareInterface>hardware_interface/PositionJointInterface</hardwareInterface>
        </joint>
        <actuator name="joint_13_motor">
            <hardwareInterface>hardware_interface/PositionJointInterface</hardwareInterface>
            <mechanicalReduction>1</mechanicalReduction>
        </actuator>
    </transmission>
    <transmission name="trans_joint_14">
        <type>transmission_interface/SimpleTransmission</type>
        <joint name="joint_14">
            <hardwareInterface>hardware_interface/PositionJointInterface</hardwareInterface>
        </joint>
        <actuator name="joint_14_motor">
            <hardwareInterface>hardware_interface/PositionJointInterface</hardwareInterface>
            <mechanicalReduction>1</mechanicalReduction>
        </actuator>
    </transmission>
    <transmission name="trans_joint_15">
        <type>transmission_interface/SimpleTransmission</type>
        <joint name="joint_15">
            <hardwareInterface>hardware_interface/PositionJointInterface</hardwareInterface>
        </joint>
        <actuator name="joint_15_motor">
            <hardwareInterface>hardware_interface/PositionJointInterface</hardwareInterface>
            <mechanicalReduction>1</mechanicalReduction>
        </actuator>
    </transmission>

    <!-- Contact sensors -->
  <gazebo reference="palm_link">
    <material>Gazebo/Grey</material>
    <mu1>0.2</mu1>
    <mu2>0.2</mu2>
  </gazebo>
  <gazebo reference="link_0">
    <material>Gazebo/Grey</material>
    <kp>100.0</kp>
    <kd>10.0</kd>
    <mu1>30.0</mu1>
    <mu2>30.0</mu2>
  </gazebo>
  <gazebo reference="link_1">
    <material>Gazebo/Grey</material>
    <kp>100.0</kp>
    <kd>10.0</kd>
    <mu1>30.0</mu1>
    <mu2>30.0</mu2>
  </gazebo>
  <gazebo reference="link_2">
    <material>Gazebo/Grey</material>
    <kp>100.0</kp>
    <kd>10.0</kd>
    <mu1>30.0</mu1>
    <mu2>30.0</mu2>
  </gazebo>
  <gazebo reference="link_3">
    <material>Gazebo/Grey</material>
    <kp>100.0</kp>
    <kd>10.0</kd>
    <mu1>30.0</mu1>
    <mu2>30.0</mu2>
  </gazebo>
  <gazebo reference="link_3_tip">
    <material>Gazebo/Grey</material>
    <kp>100.0</kp>
    <kd>10.0</kd>
    <mu1>30.0</mu1>
    <mu2>30.0</mu2>
    
    <sensor type="contact" name="link_3_tip_contact_sensor">
      <update_rate>30</update_rate>
      <always_on>true</always_on>
      <contact>
        <collision>link_3_tip_collision_collision</collision>
      </contact>
      <plugin name="link_3_tip_plugin" filename="libgazebo_ros_bumper.so">
        <bumperTopicName>aurova/link_3_tip_contact_sensor</bumperTopicName>
        <frameName>link_3_tip</frameName>
      </plugin>
    </sensor>       
  </gazebo>
  <gazebo reference="link_4">
    <material>Gazebo/Grey</material>
    <kp>100.0</kp>
    <kd>10.0</kd>
    <mu1>30.0</mu1>
    <mu2>30.0</mu2>
  </gazebo>
  <gazebo reference="link_5">
    <material>Gazebo/Grey</material>
    <kp>100.0</kp>
    <kd>10.0</kd>
    <mu1>30.0</mu1>
    <mu2>30.0</mu2>
  </gazebo>
  <gazebo reference="link_6">
    <material>Gazebo/Grey</material>
    <kp>100.0</kp>
    <kd>10.0</kd>
    <mu1>30.0</mu1>
    <mu2>30.0</mu2>
  </gazebo>
  <gazebo reference="link_7">
    <material>Gazebo/Grey</material>
    <kp>100.0</kp>
    <kd>10.0</kd>
    <mu1>30.0</mu1>
    <mu2>30.0</mu2>
  </gazebo>
  <gazebo reference="link_7_tip">
    <material>Gazebo/Grey</material>
    <kp>100.0</kp>
    <kd>10.0</kd>
    <mu1>30.0</mu1>
    <mu2>30.0</mu2>
    
    <sensor type="contact" name="link_7_tip_contact_sensor">
      <update_rate>30</update_rate>
      <always_on>true</always_on>
      <contact>
        <collision>link_7_tip_collision_collision</collision>
      </contact>
      <plugin name="link_7_tip_plugin" filename="libgazebo_ros_bumper.so">
        <bumperTopicName>aurova/link_7_tip_contact_sensor</bumperTopicName>
        <frameName>link_7_tip</frameName>
      </plugin>
    </sensor>        
  </gazebo>
  <gazebo reference="link_8">
    <material>Gazebo/Grey</material>
    <kp>100.0</kp>
    <kd>10.0</kd>
    <mu1>30.0</mu1>
    <mu2>30.0</mu2>
  </gazebo>
  <gazebo reference="link_9">
    <material>Gazebo/Grey</material>
    <kp>100.0</kp>
    <kd>10.0</kd>
    <mu1>30.0</mu1>
    <mu2>30.0</mu2>
  </gazebo>
  <gazebo reference="link_10">
    <material>Gazebo/Grey</material>
    <kp>100.0</kp>
    <kd>10.0</kd>
    <mu1>30.0</mu1>
    <mu2>30.0</mu2>
  </gazebo>
  <gazebo reference="link_11">
    <material>Gazebo/Grey</material>
    <kp>100.0</kp>
    <kd>10.0</kd>
    <mu1>30.0</mu1>
    <mu2>30.0</mu2>
  </gazebo>
  <gazebo reference="link_11_tip">
    <material>Gazebo/Grey</material>
    <kp>100.0</kp>
    <kd>10.0</kd>
    <mu1>30.0</mu1>
    <mu2>30.0</mu2>    
        
    <sensor type="contact" name="link_11_tip_contact_sensor">
      <update_rate>30</update_rate>
      <always_on>true</always_on>
      <contact>
        <collision>link_11_tip_collision_collision</collision>
      </contact>
      <plugin name="link_11_tip_plugin" filename="libgazebo_ros_bumper.so">
        <bumperTopicName>aurova/link_11_tip_contact_sensor</bumperTopicName>
        <frameName>link_11_tip</frameName>
      </plugin>
    </sensor>    
  </gazebo>
  <gazebo reference="link_12">
    <material>Gazebo/Grey</material>
    <kp>100.0</kp>
    <kd>10.0</kd>
    <mu1>30.0</mu1>
    <mu2>30.0</mu2>
  </gazebo>
  <gazebo reference="link_13">
    <material>Gazebo/Grey</material>
    <kp>100.0</kp>
    <kd>10.0</kd>
    <mu1>30.0</mu1>
    <mu2>30.0</mu2>
  </gazebo>
  <gazebo reference="link_14">
    <material>Gazebo/Grey</material>
    <kp>100.0</kp>
    <kd>10.0</kd>
    <mu1>30.0</mu1>
    <mu2>30.0</mu2>
  </gazebo>
  <gazebo reference="link_15">
    <material>Gazebo/Grey</material>
    <kp>100.0</kp>
    <kd>10.0</kd>
    <mu1>30.0</mu1>
    <mu2>30.0</mu2>
  </gazebo>
  <gazebo reference="link_15_tip">
    <material>Gazebo/Grey</material>
    <kp>100.0</kp>
    <kd>10.0</kd>
    <mu1>30.0</mu1>
    <mu2>30.0</mu2>    
        
    <sensor type="contact" name="link_15_tip_contact_sensor">
      <update_rate>30</update_rate>
      <always_on>true</always_on>
      <contact>
        <collision>link_15_tip_collision_collision</collision>
      </contact>
      <plugin name="link_15_tip_plugin" filename="libgazebo_ros_bumper.so">
        <bumperTopicName>aurova/link_15_tip_contact_sensor</bumperTopicName>
        <frameName>link_15_tip</frameName>
      </plugin>
    </sensor>    
  </gazebo>  
</robot>

